2022-01-06 22:38:36,913 ERROR: Exception on /homepage [GET] [in C:\Users\Simone Dalle Vedove\AppData\Local\Programs\Python\Python310\lib\site-packages\flask\app.py:1457]
Traceback (most recent call last):
  File "C:\Users\Simone Dalle Vedove\AppData\Local\Programs\Python\Python310\lib\site-packages\sqlalchemy\engine\base.py", line 3243, in _wrap_pool_connect
    return fn()
  File "C:\Users\Simone Dalle Vedove\AppData\Local\Programs\Python\Python310\lib\site-packages\sqlalchemy\pool\base.py", line 310, in connect
    return _ConnectionFairy._checkout(self)
  File "C:\Users\Simone Dalle Vedove\AppData\Local\Programs\Python\Python310\lib\site-packages\sqlalchemy\pool\base.py", line 868, in _checkout
    fairy = _ConnectionRecord.checkout(pool)
  File "C:\Users\Simone Dalle Vedove\AppData\Local\Programs\Python\Python310\lib\site-packages\sqlalchemy\pool\base.py", line 476, in checkout
    rec = pool._do_get()
  File "C:\Users\Simone Dalle Vedove\AppData\Local\Programs\Python\Python310\lib\site-packages\sqlalchemy\pool\impl.py", line 145, in _do_get
    with util.safe_reraise():
  File "C:\Users\Simone Dalle Vedove\AppData\Local\Programs\Python\Python310\lib\site-packages\sqlalchemy\util\langhelpers.py", line 70, in __exit__
    compat.raise_(
  File "C:\Users\Simone Dalle Vedove\AppData\Local\Programs\Python\Python310\lib\site-packages\sqlalchemy\util\compat.py", line 207, in raise_
    raise exception
  File "C:\Users\Simone Dalle Vedove\AppData\Local\Programs\Python\Python310\lib\site-packages\sqlalchemy\pool\impl.py", line 143, in _do_get
    return self._create_connection()
  File "C:\Users\Simone Dalle Vedove\AppData\Local\Programs\Python\Python310\lib\site-packages\sqlalchemy\pool\base.py", line 256, in _create_connection
    return _ConnectionRecord(self)
  File "C:\Users\Simone Dalle Vedove\AppData\Local\Programs\Python\Python310\lib\site-packages\sqlalchemy\pool\base.py", line 371, in __init__
    self.__connect()
  File "C:\Users\Simone Dalle Vedove\AppData\Local\Programs\Python\Python310\lib\site-packages\sqlalchemy\pool\base.py", line 665, in __connect
    with util.safe_reraise():
  File "C:\Users\Simone Dalle Vedove\AppData\Local\Programs\Python\Python310\lib\site-packages\sqlalchemy\util\langhelpers.py", line 70, in __exit__
    compat.raise_(
  File "C:\Users\Simone Dalle Vedove\AppData\Local\Programs\Python\Python310\lib\site-packages\sqlalchemy\util\compat.py", line 207, in raise_
    raise exception
  File "C:\Users\Simone Dalle Vedove\AppData\Local\Programs\Python\Python310\lib\site-packages\sqlalchemy\pool\base.py", line 661, in __connect
    self.dbapi_connection = connection = pool._invoke_creator(self)
  File "C:\Users\Simone Dalle Vedove\AppData\Local\Programs\Python\Python310\lib\site-packages\sqlalchemy\engine\create.py", line 590, in connect
    return dialect.connect(*cargs, **cparams)
  File "C:\Users\Simone Dalle Vedove\AppData\Local\Programs\Python\Python310\lib\site-packages\sqlalchemy\engine\default.py", line 584, in connect
    return self.dbapi.connect(*cargs, **cparams)
  File "C:\Users\Simone Dalle Vedove\AppData\Local\Programs\Python\Python310\lib\site-packages\psycopg2\__init__.py", line 122, in connect
    conn = _connect(dsn, connection_factory=connection_factory, **kwasync)
psycopg2.OperationalError: connection to server at "192.168.1.12", port 8484 failed: FATAL:  database "APP_DB_TEST" does not exist


The above exception was the direct cause of the following exception:

Traceback (most recent call last):
  File "C:\Users\Simone Dalle Vedove\AppData\Local\Programs\Python\Python310\lib\site-packages\flask\app.py", line 2073, in wsgi_app
    response = self.full_dispatch_request()
  File "C:\Users\Simone Dalle Vedove\AppData\Local\Programs\Python\Python310\lib\site-packages\flask\app.py", line 1518, in full_dispatch_request
    rv = self.handle_user_exception(e)
  File "C:\Users\Simone Dalle Vedove\AppData\Local\Programs\Python\Python310\lib\site-packages\flask\app.py", line 1514, in full_dispatch_request
    rv = self.preprocess_request()
  File "C:\Users\Simone Dalle Vedove\AppData\Local\Programs\Python\Python310\lib\site-packages\flask\app.py", line 1857, in preprocess_request
    rv = self.ensure_sync(before_func)()
  File "C:\Users\Simone Dalle Vedove\Desktop\Varie\Progetti Flask\info_copping - official\app\routes.py", line 116, in before_request
    if current_user.is_authenticated:
  File "C:\Users\Simone Dalle Vedove\AppData\Local\Programs\Python\Python310\lib\site-packages\werkzeug\local.py", line 432, in __get__
    obj = instance._get_current_object()
  File "C:\Users\Simone Dalle Vedove\AppData\Local\Programs\Python\Python310\lib\site-packages\werkzeug\local.py", line 554, in _get_current_object
    return self.__local()  # type: ignore
  File "C:\Users\Simone Dalle Vedove\AppData\Local\Programs\Python\Python310\lib\site-packages\flask_login\utils.py", line 26, in <lambda>
    current_user = LocalProxy(lambda: _get_user())
  File "C:\Users\Simone Dalle Vedove\AppData\Local\Programs\Python\Python310\lib\site-packages\flask_login\utils.py", line 346, in _get_user
    current_app.login_manager._load_user()
  File "C:\Users\Simone Dalle Vedove\AppData\Local\Programs\Python\Python310\lib\site-packages\flask_login\login_manager.py", line 318, in _load_user
    user = self._user_callback(user_id)
  File "C:\Users\Simone Dalle Vedove\Desktop\Varie\Progetti Flask\info_copping - official\app\models.py", line 104, in load_user
    return User.query.get(int(id))
  File "<string>", line 2, in get
  File "C:\Users\Simone Dalle Vedove\AppData\Local\Programs\Python\Python310\lib\site-packages\sqlalchemy\util\deprecations.py", line 401, in warned
    return fn(*args, **kwargs)
  File "C:\Users\Simone Dalle Vedove\AppData\Local\Programs\Python\Python310\lib\site-packages\sqlalchemy\orm\query.py", line 943, in get
    return self._get_impl(ident, loading.load_on_pk_identity)
  File "C:\Users\Simone Dalle Vedove\AppData\Local\Programs\Python\Python310\lib\site-packages\sqlalchemy\orm\query.py", line 947, in _get_impl
    return self.session._get_impl(
  File "C:\Users\Simone Dalle Vedove\AppData\Local\Programs\Python\Python310\lib\site-packages\sqlalchemy\orm\session.py", line 2874, in _get_impl
    return db_load_fn(
  File "C:\Users\Simone Dalle Vedove\AppData\Local\Programs\Python\Python310\lib\site-packages\sqlalchemy\orm\loading.py", line 530, in load_on_pk_identity
    session.execute(
  File "C:\Users\Simone Dalle Vedove\AppData\Local\Programs\Python\Python310\lib\site-packages\sqlalchemy\orm\session.py", line 1688, in execute
    conn = self._connection_for_bind(bind)
  File "C:\Users\Simone Dalle Vedove\AppData\Local\Programs\Python\Python310\lib\site-packages\sqlalchemy\orm\session.py", line 1529, in _connection_for_bind
    return self._transaction._connection_for_bind(
  File "C:\Users\Simone Dalle Vedove\AppData\Local\Programs\Python\Python310\lib\site-packages\sqlalchemy\orm\session.py", line 747, in _connection_for_bind
    conn = bind.connect()
  File "C:\Users\Simone Dalle Vedove\AppData\Local\Programs\Python\Python310\lib\site-packages\sqlalchemy\engine\base.py", line 3197, in connect
    return self._connection_cls(self, close_with_result=close_with_result)
  File "C:\Users\Simone Dalle Vedove\AppData\Local\Programs\Python\Python310\lib\site-packages\sqlalchemy\engine\base.py", line 96, in __init__
    else engine.raw_connection()
  File "C:\Users\Simone Dalle Vedove\AppData\Local\Programs\Python\Python310\lib\site-packages\sqlalchemy\engine\base.py", line 3276, in raw_connection
    return self._wrap_pool_connect(self.pool.connect, _connection)
  File "C:\Users\Simone Dalle Vedove\AppData\Local\Programs\Python\Python310\lib\site-packages\sqlalchemy\engine\base.py", line 3246, in _wrap_pool_connect
    Connection._handle_dbapi_exception_noconnection(
  File "C:\Users\Simone Dalle Vedove\AppData\Local\Programs\Python\Python310\lib\site-packages\sqlalchemy\engine\base.py", line 2100, in _handle_dbapi_exception_noconnection
    util.raise_(
  File "C:\Users\Simone Dalle Vedove\AppData\Local\Programs\Python\Python310\lib\site-packages\sqlalchemy\util\compat.py", line 207, in raise_
    raise exception
  File "C:\Users\Simone Dalle Vedove\AppData\Local\Programs\Python\Python310\lib\site-packages\sqlalchemy\engine\base.py", line 3243, in _wrap_pool_connect
    return fn()
  File "C:\Users\Simone Dalle Vedove\AppData\Local\Programs\Python\Python310\lib\site-packages\sqlalchemy\pool\base.py", line 310, in connect
    return _ConnectionFairy._checkout(self)
  File "C:\Users\Simone Dalle Vedove\AppData\Local\Programs\Python\Python310\lib\site-packages\sqlalchemy\pool\base.py", line 868, in _checkout
    fairy = _ConnectionRecord.checkout(pool)
  File "C:\Users\Simone Dalle Vedove\AppData\Local\Programs\Python\Python310\lib\site-packages\sqlalchemy\pool\base.py", line 476, in checkout
    rec = pool._do_get()
  File "C:\Users\Simone Dalle Vedove\AppData\Local\Programs\Python\Python310\lib\site-packages\sqlalchemy\pool\impl.py", line 145, in _do_get
    with util.safe_reraise():
  File "C:\Users\Simone Dalle Vedove\AppData\Local\Programs\Python\Python310\lib\site-packages\sqlalchemy\util\langhelpers.py", line 70, in __exit__
    compat.raise_(
  File "C:\Users\Simone Dalle Vedove\AppData\Local\Programs\Python\Python310\lib\site-packages\sqlalchemy\util\compat.py", line 207, in raise_
    raise exception
  File "C:\Users\Simone Dalle Vedove\AppData\Local\Programs\Python\Python310\lib\site-packages\sqlalchemy\pool\impl.py", line 143, in _do_get
    return self._create_connection()
  File "C:\Users\Simone Dalle Vedove\AppData\Local\Programs\Python\Python310\lib\site-packages\sqlalchemy\pool\base.py", line 256, in _create_connection
    return _ConnectionRecord(self)
  File "C:\Users\Simone Dalle Vedove\AppData\Local\Programs\Python\Python310\lib\site-packages\sqlalchemy\pool\base.py", line 371, in __init__
    self.__connect()
  File "C:\Users\Simone Dalle Vedove\AppData\Local\Programs\Python\Python310\lib\site-packages\sqlalchemy\pool\base.py", line 665, in __connect
    with util.safe_reraise():
  File "C:\Users\Simone Dalle Vedove\AppData\Local\Programs\Python\Python310\lib\site-packages\sqlalchemy\util\langhelpers.py", line 70, in __exit__
    compat.raise_(
  File "C:\Users\Simone Dalle Vedove\AppData\Local\Programs\Python\Python310\lib\site-packages\sqlalchemy\util\compat.py", line 207, in raise_
    raise exception
  File "C:\Users\Simone Dalle Vedove\AppData\Local\Programs\Python\Python310\lib\site-packages\sqlalchemy\pool\base.py", line 661, in __connect
    self.dbapi_connection = connection = pool._invoke_creator(self)
  File "C:\Users\Simone Dalle Vedove\AppData\Local\Programs\Python\Python310\lib\site-packages\sqlalchemy\engine\create.py", line 590, in connect
    return dialect.connect(*cargs, **cparams)
  File "C:\Users\Simone Dalle Vedove\AppData\Local\Programs\Python\Python310\lib\site-packages\sqlalchemy\engine\default.py", line 584, in connect
    return self.dbapi.connect(*cargs, **cparams)
  File "C:\Users\Simone Dalle Vedove\AppData\Local\Programs\Python\Python310\lib\site-packages\psycopg2\__init__.py", line 122, in connect
    conn = _connect(dsn, connection_factory=connection_factory, **kwasync)
sqlalchemy.exc.OperationalError: (psycopg2.OperationalError) connection to server at "192.168.1.12", port 8484 failed: FATAL:  database "APP_DB_TEST" does not exist

(Background on this error at: https://sqlalche.me/e/14/e3q8)
