2022-03-08 14:29:57,780 ERROR: Exception on /login [POST] [in C:\Users\Simone Dalle Vedove\AppData\Local\Programs\Python\Python310\lib\site-packages\flask\app.py:1457]
Traceback (most recent call last):
  File "C:\Users\Simone Dalle Vedove\AppData\Local\Programs\Python\Python310\lib\site-packages\sqlalchemy\engine\base.py", line 3243, in _wrap_pool_connect
    return fn()
  File "C:\Users\Simone Dalle Vedove\AppData\Local\Programs\Python\Python310\lib\site-packages\sqlalchemy\pool\base.py", line 310, in connect
    return _ConnectionFairy._checkout(self)
  File "C:\Users\Simone Dalle Vedove\AppData\Local\Programs\Python\Python310\lib\site-packages\sqlalchemy\pool\base.py", line 868, in _checkout
    fairy = _ConnectionRecord.checkout(pool)
  File "C:\Users\Simone Dalle Vedove\AppData\Local\Programs\Python\Python310\lib\site-packages\sqlalchemy\pool\base.py", line 476, in checkout
    rec = pool._do_get()
  File "C:\Users\Simone Dalle Vedove\AppData\Local\Programs\Python\Python310\lib\site-packages\sqlalchemy\pool\impl.py", line 145, in _do_get
    with util.safe_reraise():
  File "C:\Users\Simone Dalle Vedove\AppData\Local\Programs\Python\Python310\lib\site-packages\sqlalchemy\util\langhelpers.py", line 70, in __exit__
    compat.raise_(
  File "C:\Users\Simone Dalle Vedove\AppData\Local\Programs\Python\Python310\lib\site-packages\sqlalchemy\util\compat.py", line 207, in raise_
    raise exception
  File "C:\Users\Simone Dalle Vedove\AppData\Local\Programs\Python\Python310\lib\site-packages\sqlalchemy\pool\impl.py", line 143, in _do_get
    return self._create_connection()
  File "C:\Users\Simone Dalle Vedove\AppData\Local\Programs\Python\Python310\lib\site-packages\sqlalchemy\pool\base.py", line 256, in _create_connection
    return _ConnectionRecord(self)
  File "C:\Users\Simone Dalle Vedove\AppData\Local\Programs\Python\Python310\lib\site-packages\sqlalchemy\pool\base.py", line 371, in __init__
    self.__connect()
  File "C:\Users\Simone Dalle Vedove\AppData\Local\Programs\Python\Python310\lib\site-packages\sqlalchemy\pool\base.py", line 665, in __connect
    with util.safe_reraise():
  File "C:\Users\Simone Dalle Vedove\AppData\Local\Programs\Python\Python310\lib\site-packages\sqlalchemy\util\langhelpers.py", line 70, in __exit__
    compat.raise_(
  File "C:\Users\Simone Dalle Vedove\AppData\Local\Programs\Python\Python310\lib\site-packages\sqlalchemy\util\compat.py", line 207, in raise_
    raise exception
  File "C:\Users\Simone Dalle Vedove\AppData\Local\Programs\Python\Python310\lib\site-packages\sqlalchemy\pool\base.py", line 661, in __connect
    self.dbapi_connection = connection = pool._invoke_creator(self)
  File "C:\Users\Simone Dalle Vedove\AppData\Local\Programs\Python\Python310\lib\site-packages\sqlalchemy\engine\create.py", line 590, in connect
    return dialect.connect(*cargs, **cparams)
  File "C:\Users\Simone Dalle Vedove\AppData\Local\Programs\Python\Python310\lib\site-packages\sqlalchemy\engine\default.py", line 584, in connect
    return self.dbapi.connect(*cargs, **cparams)
  File "C:\Users\Simone Dalle Vedove\AppData\Local\Programs\Python\Python310\lib\site-packages\psycopg2\__init__.py", line 122, in connect
    conn = _connect(dsn, connection_factory=connection_factory, **kwasync)
psycopg2.OperationalError: connection to server at "localhost" (::1), port 5432 failed: Connection refused (0x0000274D/10061)
	Is the server running on that host and accepting TCP/IP connections?
connection to server at "localhost" (127.0.0.1), port 5432 failed: Connection refused (0x0000274D/10061)
	Is the server running on that host and accepting TCP/IP connections?


The above exception was the direct cause of the following exception:

Traceback (most recent call last):
  File "C:\Users\Simone Dalle Vedove\AppData\Local\Programs\Python\Python310\lib\site-packages\flask\app.py", line 2073, in wsgi_app
    response = self.full_dispatch_request()
  File "C:\Users\Simone Dalle Vedove\AppData\Local\Programs\Python\Python310\lib\site-packages\flask\app.py", line 1518, in full_dispatch_request
    rv = self.handle_user_exception(e)
  File "C:\Users\Simone Dalle Vedove\AppData\Local\Programs\Python\Python310\lib\site-packages\flask\app.py", line 1516, in full_dispatch_request
    rv = self.dispatch_request()
  File "C:\Users\Simone Dalle Vedove\AppData\Local\Programs\Python\Python310\lib\site-packages\flask\app.py", line 1502, in dispatch_request
    return self.ensure_sync(self.view_functions[rule.endpoint])(**req.view_args)
  File "C:\Users\Simone Dalle Vedove\Desktop\Varie\Progetti Flask\info_copping_app\app\routes.py", line 96, in login
    user = User.query.filter_by(username=form.username.data).first()
  File "C:\Users\Simone Dalle Vedove\AppData\Local\Programs\Python\Python310\lib\site-packages\sqlalchemy\orm\query.py", line 2810, in first
    return self.limit(1)._iter().first()
  File "C:\Users\Simone Dalle Vedove\AppData\Local\Programs\Python\Python310\lib\site-packages\sqlalchemy\orm\query.py", line 2894, in _iter
    result = self.session.execute(
  File "C:\Users\Simone Dalle Vedove\AppData\Local\Programs\Python\Python310\lib\site-packages\sqlalchemy\orm\session.py", line 1688, in execute
    conn = self._connection_for_bind(bind)
  File "C:\Users\Simone Dalle Vedove\AppData\Local\Programs\Python\Python310\lib\site-packages\sqlalchemy\orm\session.py", line 1529, in _connection_for_bind
    return self._transaction._connection_for_bind(
  File "C:\Users\Simone Dalle Vedove\AppData\Local\Programs\Python\Python310\lib\site-packages\sqlalchemy\orm\session.py", line 747, in _connection_for_bind
    conn = bind.connect()
  File "C:\Users\Simone Dalle Vedove\AppData\Local\Programs\Python\Python310\lib\site-packages\sqlalchemy\engine\base.py", line 3197, in connect
    return self._connection_cls(self, close_with_result=close_with_result)
  File "C:\Users\Simone Dalle Vedove\AppData\Local\Programs\Python\Python310\lib\site-packages\sqlalchemy\engine\base.py", line 96, in __init__
    else engine.raw_connection()
  File "C:\Users\Simone Dalle Vedove\AppData\Local\Programs\Python\Python310\lib\site-packages\sqlalchemy\engine\base.py", line 3276, in raw_connection
    return self._wrap_pool_connect(self.pool.connect, _connection)
  File "C:\Users\Simone Dalle Vedove\AppData\Local\Programs\Python\Python310\lib\site-packages\sqlalchemy\engine\base.py", line 3246, in _wrap_pool_connect
    Connection._handle_dbapi_exception_noconnection(
  File "C:\Users\Simone Dalle Vedove\AppData\Local\Programs\Python\Python310\lib\site-packages\sqlalchemy\engine\base.py", line 2100, in _handle_dbapi_exception_noconnection
    util.raise_(
  File "C:\Users\Simone Dalle Vedove\AppData\Local\Programs\Python\Python310\lib\site-packages\sqlalchemy\util\compat.py", line 207, in raise_
    raise exception
  File "C:\Users\Simone Dalle Vedove\AppData\Local\Programs\Python\Python310\lib\site-packages\sqlalchemy\engine\base.py", line 3243, in _wrap_pool_connect
    return fn()
  File "C:\Users\Simone Dalle Vedove\AppData\Local\Programs\Python\Python310\lib\site-packages\sqlalchemy\pool\base.py", line 310, in connect
    return _ConnectionFairy._checkout(self)
  File "C:\Users\Simone Dalle Vedove\AppData\Local\Programs\Python\Python310\lib\site-packages\sqlalchemy\pool\base.py", line 868, in _checkout
    fairy = _ConnectionRecord.checkout(pool)
  File "C:\Users\Simone Dalle Vedove\AppData\Local\Programs\Python\Python310\lib\site-packages\sqlalchemy\pool\base.py", line 476, in checkout
    rec = pool._do_get()
  File "C:\Users\Simone Dalle Vedove\AppData\Local\Programs\Python\Python310\lib\site-packages\sqlalchemy\pool\impl.py", line 145, in _do_get
    with util.safe_reraise():
  File "C:\Users\Simone Dalle Vedove\AppData\Local\Programs\Python\Python310\lib\site-packages\sqlalchemy\util\langhelpers.py", line 70, in __exit__
    compat.raise_(
  File "C:\Users\Simone Dalle Vedove\AppData\Local\Programs\Python\Python310\lib\site-packages\sqlalchemy\util\compat.py", line 207, in raise_
    raise exception
  File "C:\Users\Simone Dalle Vedove\AppData\Local\Programs\Python\Python310\lib\site-packages\sqlalchemy\pool\impl.py", line 143, in _do_get
    return self._create_connection()
  File "C:\Users\Simone Dalle Vedove\AppData\Local\Programs\Python\Python310\lib\site-packages\sqlalchemy\pool\base.py", line 256, in _create_connection
    return _ConnectionRecord(self)
  File "C:\Users\Simone Dalle Vedove\AppData\Local\Programs\Python\Python310\lib\site-packages\sqlalchemy\pool\base.py", line 371, in __init__
    self.__connect()
  File "C:\Users\Simone Dalle Vedove\AppData\Local\Programs\Python\Python310\lib\site-packages\sqlalchemy\pool\base.py", line 665, in __connect
    with util.safe_reraise():
  File "C:\Users\Simone Dalle Vedove\AppData\Local\Programs\Python\Python310\lib\site-packages\sqlalchemy\util\langhelpers.py", line 70, in __exit__
    compat.raise_(
  File "C:\Users\Simone Dalle Vedove\AppData\Local\Programs\Python\Python310\lib\site-packages\sqlalchemy\util\compat.py", line 207, in raise_
    raise exception
  File "C:\Users\Simone Dalle Vedove\AppData\Local\Programs\Python\Python310\lib\site-packages\sqlalchemy\pool\base.py", line 661, in __connect
    self.dbapi_connection = connection = pool._invoke_creator(self)
  File "C:\Users\Simone Dalle Vedove\AppData\Local\Programs\Python\Python310\lib\site-packages\sqlalchemy\engine\create.py", line 590, in connect
    return dialect.connect(*cargs, **cparams)
  File "C:\Users\Simone Dalle Vedove\AppData\Local\Programs\Python\Python310\lib\site-packages\sqlalchemy\engine\default.py", line 584, in connect
    return self.dbapi.connect(*cargs, **cparams)
  File "C:\Users\Simone Dalle Vedove\AppData\Local\Programs\Python\Python310\lib\site-packages\psycopg2\__init__.py", line 122, in connect
    conn = _connect(dsn, connection_factory=connection_factory, **kwasync)
sqlalchemy.exc.OperationalError: (psycopg2.OperationalError) connection to server at "localhost" (::1), port 5432 failed: Connection refused (0x0000274D/10061)
	Is the server running on that host and accepting TCP/IP connections?
connection to server at "localhost" (127.0.0.1), port 5432 failed: Connection refused (0x0000274D/10061)
	Is the server running on that host and accepting TCP/IP connections?

(Background on this error at: https://sqlalche.me/e/14/e3q8)
