2022-03-09 07:49:30,270 ERROR: Exception on /homepage [GET] [in C:\Users\Simone Dalle Vedove\AppData\Local\Programs\Python\Python310\lib\site-packages\flask\app.py:1457]
Traceback (most recent call last):
  File "C:\Users\Simone Dalle Vedove\AppData\Local\Programs\Python\Python310\lib\site-packages\sqlalchemy\engine\base.py", line 1802, in _execute_context
    self.dialect.do_execute(
  File "C:\Users\Simone Dalle Vedove\AppData\Local\Programs\Python\Python310\lib\site-packages\sqlalchemy\engine\default.py", line 719, in do_execute
    cursor.execute(statement, parameters)
psycopg2.errors.UndefinedColumn: column item.region does not exist
LINE 2: ..., item.stato AS item_stato, item.sku AS item_sku, item.regio...
                                                             ^


The above exception was the direct cause of the following exception:

Traceback (most recent call last):
  File "C:\Users\Simone Dalle Vedove\AppData\Local\Programs\Python\Python310\lib\site-packages\flask\app.py", line 2073, in wsgi_app
    response = self.full_dispatch_request()
  File "C:\Users\Simone Dalle Vedove\AppData\Local\Programs\Python\Python310\lib\site-packages\flask\app.py", line 1518, in full_dispatch_request
    rv = self.handle_user_exception(e)
  File "C:\Users\Simone Dalle Vedove\AppData\Local\Programs\Python\Python310\lib\site-packages\flask\app.py", line 1516, in full_dispatch_request
    rv = self.dispatch_request()
  File "C:\Users\Simone Dalle Vedove\AppData\Local\Programs\Python\Python310\lib\site-packages\flask\app.py", line 1502, in dispatch_request
    return self.ensure_sync(self.view_functions[rule.endpoint])(**req.view_args)
  File "C:\Users\Simone Dalle Vedove\AppData\Local\Programs\Python\Python310\lib\site-packages\flask_login\utils.py", line 272, in decorated_view
    return func(*args, **kwargs)
  File "C:\Users\Simone Dalle Vedove\Desktop\Varie\Progetti Flask\info_copping_app\app\routes.py", line 26, in homepage
    .count()
  File "C:\Users\Simone Dalle Vedove\AppData\Local\Programs\Python\Python310\lib\site-packages\sqlalchemy\orm\query.py", line 3145, in count
    return self._from_self(col).enable_eagerloads(False).scalar()
  File "C:\Users\Simone Dalle Vedove\AppData\Local\Programs\Python\Python310\lib\site-packages\sqlalchemy\orm\query.py", line 2879, in scalar
    ret = self.one()
  File "C:\Users\Simone Dalle Vedove\AppData\Local\Programs\Python\Python310\lib\site-packages\sqlalchemy\orm\query.py", line 2856, in one
    return self._iter().one()
  File "C:\Users\Simone Dalle Vedove\AppData\Local\Programs\Python\Python310\lib\site-packages\sqlalchemy\orm\query.py", line 2894, in _iter
    result = self.session.execute(
  File "C:\Users\Simone Dalle Vedove\AppData\Local\Programs\Python\Python310\lib\site-packages\sqlalchemy\orm\session.py", line 1689, in execute
    result = conn._execute_20(statement, params or {}, execution_options)
  File "C:\Users\Simone Dalle Vedove\AppData\Local\Programs\Python\Python310\lib\site-packages\sqlalchemy\engine\base.py", line 1614, in _execute_20
    return meth(self, args_10style, kwargs_10style, execution_options)
  File "C:\Users\Simone Dalle Vedove\AppData\Local\Programs\Python\Python310\lib\site-packages\sqlalchemy\sql\elements.py", line 325, in _execute_on_connection
    return connection._execute_clauseelement(
  File "C:\Users\Simone Dalle Vedove\AppData\Local\Programs\Python\Python310\lib\site-packages\sqlalchemy\engine\base.py", line 1481, in _execute_clauseelement
    ret = self._execute_context(
  File "C:\Users\Simone Dalle Vedove\AppData\Local\Programs\Python\Python310\lib\site-packages\sqlalchemy\engine\base.py", line 1845, in _execute_context
    self._handle_dbapi_exception(
  File "C:\Users\Simone Dalle Vedove\AppData\Local\Programs\Python\Python310\lib\site-packages\sqlalchemy\engine\base.py", line 2026, in _handle_dbapi_exception
    util.raise_(
  File "C:\Users\Simone Dalle Vedove\AppData\Local\Programs\Python\Python310\lib\site-packages\sqlalchemy\util\compat.py", line 207, in raise_
    raise exception
  File "C:\Users\Simone Dalle Vedove\AppData\Local\Programs\Python\Python310\lib\site-packages\sqlalchemy\engine\base.py", line 1802, in _execute_context
    self.dialect.do_execute(
  File "C:\Users\Simone Dalle Vedove\AppData\Local\Programs\Python\Python310\lib\site-packages\sqlalchemy\engine\default.py", line 719, in do_execute
    cursor.execute(statement, parameters)
sqlalchemy.exc.ProgrammingError: (psycopg2.errors.UndefinedColumn) column item.region does not exist
LINE 2: ..., item.stato AS item_stato, item.sku AS item_sku, item.regio...
                                                             ^

[SQL: SELECT count(*) AS count_1 
FROM (SELECT item.id AS item_id, item.codice AS item_codice, item.descrizione AS item_descrizione, item.stato AS item_stato, item.sku AS item_sku, item.region AS item_region, item.prezzo AS item_prezzo, item.spedizione_acquisto AS item_spedizione_acquisto, item.reship AS item_reship, item.slot AS item_slot, item.data_ordine AS item_data_ordine, item.consegna_stesso_giorno AS item_consegna_stesso_giorno, item.data_consegna AS item_data_consegna, item.data_scadenza_reso AS item_data_scadenza_reso, item.proxy AS item_proxy, item.bot AS item_bot, item.negozio AS item_negozio, item.taglia AS item_taglia, item.incasso AS item_incasso, item.spedizione_vendita AS item_spedizione_vendita, item.fee_reship AS item_fee_reship, item.data_vendita AS item_data_vendita, item.incasso_stesso_giorno AS item_incasso_stesso_giorno, item.data_incasso AS item_data_incasso, item.canale AS item_canale, item.contatto AS item_contatto, item.tipologia AS item_tipologia, item.prezzo_totale AS item_prezzo_totale, item.ricavi_lordi AS item_ricavi_lordi, item.ricavi_netti AS item_ricavi_netti, item.data_creazione AS item_data_creazione, item.user_id AS item_user_id 
FROM item 
WHERE item.user_id = %(user_id_1)s AND EXTRACT(month FROM item.data_ordine) = EXTRACT(month FROM %(param_1)s) AND EXTRACT(year FROM item.data_ordine) = EXTRACT(year FROM %(param_2)s)) AS anon_1]
[parameters: {'user_id_1': 1, 'param_1': datetime.datetime(2022, 3, 9, 7, 49, 30, 261155), 'param_2': datetime.datetime(2022, 3, 9, 7, 49, 30, 261155)}]
(Background on this error at: https://sqlalche.me/e/14/f405)
2022-03-09 07:55:36,746 INFO: Info Copping startup [in C:\Users\Simone Dalle Vedove\Desktop\Varie\Progetti Flask\info_copping_app\app\__init__.py:47]
2022-03-11 09:09:35,470 INFO: Info Copping startup [in C:\Users\Simone Dalle Vedove\Desktop\Varie\Progetti Flask\info_copping_app\app\__init__.py:47]
2022-03-11 09:26:36,052 INFO: Info Copping startup [in C:\Users\Simone Dalle Vedove\Desktop\Varie\Progetti Flask\info_copping_app\app\__init__.py:47]
2022-03-11 09:33:34,025 INFO: Info Copping startup [in C:\Users\Simone Dalle Vedove\Desktop\Varie\Progetti Flask\info_copping_app\app\__init__.py:47]
2022-03-23 10:12:58,981 INFO: Info Copping startup [in C:\Users\Simone Dalle Vedove\Desktop\Varie\Progetti Flask\info_copping_app\app\__init__.py:47]
2022-04-01 08:06:07,327 INFO: Info Copping startup [in C:\Users\Simone Dalle Vedove\Desktop\Varie\Progetti Flask\info_copping_app\app\__init__.py:45]
